File: src/litho/data/.ipynb_checkpoints/shf_data_mem-checkpoint.txt
Longitude	Latitude	Heat Flow [mW/m2]	Error [mW/m2]	Reference	Data Type
index lon lat shf error
0 -78.757	-11.425	42	4.24	1	1
1 -78.757	-11.41	40	4.08	1	1
2 -78.765	-11.413	41	4.16	1	1
3 -78.765	-11.415	42	4.32	1	1
4 -78.798	-11.425	35	3.6	1	1
5 -79.212	-11.152	49	7.35	1	1
6 -79.2	-11.142	49	7.35	1	1
7 -78.272	-11.063	27.5	2.5	1	1
8 -78.078	-11.065	45	25	1	1
9 -76.892	-13.48	45	9.13	1	1
-76.991	-12.863	60	10	1	1
-78.943	-11.538	46	9.13	1	1
-68.75	-33.25	63	12.6	2	2
-63.45	-20.983	47	9.4	2	2
-63.183	-20.933	50	10	2	2
-66.067	-20.9	70	14	2	2
-63.2	-20.433	55	11	2	2
-63.567	-20.017	33	6.6	2	2
-63.217	-19.3	54	10.8	2	2
-63.017	-17.933	53	10.6	2	2
-63.533	-17.533	50	10	2	2
-63.267	-17.517	56	11.2	2	2
-64.067	-17.1	59	11.8	2	2
-69	-54	96	19.2	2	2
-73.607	-37.663	63	12.6	2	2
-73.5	-37.431	79	15.8	2	2
-69.917	-19.709	93	18.6	2	2
-73.75	-15.517	44	8.8	3	2
-71.35	-14.9	32	4.8	3	2
-71.567	-16.55	44	4.4	3	2
-70.65	-17.267	66	3.3	3	2
-76.75	-10.483	17	3.4	3	2
-76.6	-12.683	35	3.5	3	2
-70.767	-17.067	57	8.55	3	2
-66.817	-18.167	90	27	3	2
-68.233	-17.567	73	14.6	3	2
-67.733	-16.417	68	6.8	3	2
-71.417	-14.9	75	nan	4	2
-70.3	-16.933	50	nan	4	2
-66.48	-24.017	125	nan	4	3
-66.45	-24.27	121	nan	4	3
-66.55	-24.37	100	nan	4	3
-68.467	-27.7	81.7	nan	4	3
-68.333	-28.033	78	nan	4	3
-68.37	-27.333	100	nan	4	3
-68.083	-26.92	105	nan	4	3
-68.767	-27.917	77	nan	4	3
-66.583	-21.033	75	nan	4	2
-66.05	-21.25	70	nan	4	2
-66.683	-21.3	94	nan	4	2
-67.183	-19.383	83	nan	4	2
-66.133	-21.167	94	nan	4	2
-69.5	-15.5	55	nan	4	4
-64.283	-22.767	27	nan	4	2
-66.833	-18.467	109	nan	4	2
-66.583	-18.417	66	nan	4	2
-67.133	-17.383	75	nan	4	2
-69.017	-15.783	99	nan	4	2
-66.833	-18.283	112	nan	4	2
-69.05	-15.767	106	nan	4	2
-67.533	-17.067	62	nan	4	2
-70.5	-35.27	102	nan	4	3
-70.417	-33.417	78	nan	4	3
-70.05	-33.833	101	nan	4	3
-70.667	-33.45	93	nan	4	3
-71.567	-36.267	128	nan	4	3
-70.633	-33.167	97	nan	4	3
-70.167	-33.467	61	nan	4	2
-70.75	-33.333	79	nan	4	2
-70.717	-28.083	23	nan	4	3
-70.35	-27.1	36	nan	4	3
-70.383	-27.267	36	nan	4	3
-70.3	-26.533	10	nan	4	3
-71.583	-30.717	72	nan	4	3
-70.833	-28.983	36	nan	4	3
-72.283	-40.2	110	nan	4	3
-70.333	-35.27	88	nan	4	3
-69.32	-28.7	72	nan	4	3
-69.87	-35.17	85	nan	4	3
-69.97	-35.17	85	nan	4	3
-69.67	-29.32	76	nan	4	3
-71.13	-37.58	80	nan	4	3
-69.93	-32.68	70	nan	4	3
-70.05	-34.75	104	nan	4	3
-71.083	-37.52	95	nan	4	3
-69.567	-26.25	75	nan	4	3
-71.6	-16.5	41	nan	4	2
-70.517	-16.85	42	nan	4	2
-62.617	-39.65	77	nan	4	3
-62.7	-39.5	69	nan	4	3
-62.3	-38.32	55	nan	4	3
-63.25	-38.683	77	nan	4	3
-78.878	-11.187	59.1	5	5	4
-78.682	-11.115	35.9	7	5	4
-78.677	-11.113	41.1	7	5	4
-78.669	-11.109	34.7	6	5	4
-78.957	-11.583	48.4	10	5	4
-78.95	-11.577	45.1	9	5	4
-78.943	-11.571	42.3	10	5	4
-78.936	-11.566	47.1	10	5	4
-78.929	-11.56	51.7	10	5	4
-78.922	-11.571	52	11	5	4
-78.907	-11.542	55.4	11	5	4
-71.647	-15.1	110	nan	6	3
-74.45	-41	38.3	7.66	7	4
-73.682	-36.219	34.9	6.98	7	4
-73.566	-36.16	35.7	7.14	7	4
-70.8	-21.979	35.5	nan	8	4
-70.718	-22.19	43	nan	8	4
-70.832	-23.759	17	nan	8	4
-70.989	-23.973	37.8	nan	8	4
-70.805	-23.763	7	nan	8	4
-71.053	-23.42	27.5	nan	8	4
-68.232	-23.28	17	2.89	9	2
-70.182	-22.678	17	2.89	9	2
-70.093	-23.433	24	4.08	9	2
-68.915	-22.372	55	9.35	9	2
-68.913	-22.818	47	7.99	9	2
-63.418	-18.88	40	6.8	9	2
-64.348	-22.682	39	6.63	9	2
-63.488	-21.123	38	6.46	9	2
-63.563	-20.083	21	3.57	9	2
-63.547	-17.53	36	6.12	9	2
-64.262	-17.055	42	7.14	9	2
-63.268	-17.518	43	7.31	9	2
-63.22	-19.3	40	6.8	9	2
-63.578	-20.265	38	6.46	9	2
-63.598	-21.992	55	9.35	9	2
-63.947	-20.042	32	5.44	9	2
-62.933	-17.545	54	9.18	9	2
-62.29	-17.995	37	6.29	9	2
-63.1	-21.173	49	8.33	9	2
-62.965	-17.972	38	6.46	9	2
-63.215	-20.762	43	7.31	9	2
-62.907	-18.16	43	7.31	9	2
-63.283	-18.487	39	6.63	9	2
-63.528	-19.14	36	6.12	9	2
-62.222	-18.375	45	7.65	9	2
-63.288	-21.245	42	7.14	9	2
-63.185	-20.93	47	7.99	9	2
-64.038	-17.018	43	7.31	9	2
-62.957	-20.252	38	6.46	9	2
-73.546	-37.652	63	nan	10	2
-73.633	-37.64	172	nan	10	2
-69.917	-19.683	93	nan	10	2
-72.833	-38.583	89	nan	10	2
-75.578	-42.841	72	nan	11	4
-75.566	-42.839	68	nan	11	4
-75.554	-42.838	62	nan	11	4
-75.542	-42.837	60	nan	11	4
-75.53	-42.835	59	nan	11	4
-75.53	-42.835	59	nan	11	4
-75.206	-42.793	59	nan	11	4
-75.074	-40.68	31	nan	11	4
-75.062	-40.679	33	nan	11	4
-75.05	-40.678	39	nan	11	4
-75.038	-40.677	27	nan	11	4
-75.026	-40.675	40	nan	11	4
-75.015	-40.674	47	nan	11	4
-73.738	-36.212	52.5	nan	12	1
-73.748	-36.21	41.9	nan	12	1
-73.76	-36.209	42.4	nan	12	1
-73.77	-36.208	41.8	nan	12	1
-73.781	-36.206	42.9	nan	12	1
-73.792	-36.204	42.7	nan	12	1
-73.804	-36.203	33.8	nan	12	1
-73.829	-36.199	37.1	nan	12	1
-73.836	-36.198	39.7	nan	12	1
-74.178	-36.151	19.3	nan	12	1
-74.154	-36.152	20.2	nan	12	1
-74.131	-36.156	21.8	nan	12	1
-74.111	-36.161	20.8	nan	12	1
-74.071	-36.165	33.2	nan	12	1
-74.057	-36.167	41.3	nan	12	1
-74.037	-36.169	59.4	nan	12	1
-74.017	-36.172	45.3	nan	12	1
-74.005	-36.175	55	nan	12	1
-73.994	-36.176	48.8	nan	12	1
-73.985	-36.178	58.3	nan	12	1
-73.972	-36.18	49.2	nan	12	1
-72.356	-33.472	34	nan	13	4
-72.337	-33.478	38	nan	13	4
-72.318	-33.481	46	nan	13	4
-72.301	-33.484	50	nan	13	4
-72.281	-33.489	57	nan	13	4
-72.262	-33.493	53	nan	13	4
-72.244	-33.497	52	nan	13	4
-72.225	-33.502	55	nan	13	4
-72.206	-33.506	59	nan	13	4
-72.187	-33.051	68	nan	13	4
-72.416	-33.46	34	nan	13	4
-72.395	-33.463	34	nan	13	4
-72.376	-33.467	37	nan	13	4
-72.264	-33.502	51	nan	13	4
-72.265	-33.511	56	nan	13	4
-72.268	-33.518	55	nan	13	4
-72.271	-33.526	54	nan	13	4
-72.273	-33.534	56	nan	13	4
-72.276	-33.542	58	nan	13	4
-72.278	-33.55	56	nan	13	4
-72.28	-33.558	57	nan	13	4
-73.285	-35.268	40	nan	13	4
-73.268	-35.271	50	nan	13	4
-73.249	-35.277	57	nan	13	4
-73.229	-35.281	53	nan	13	4
-73.21	-35.287	52	nan	13	4
-73.191	-35.293	44	nan	13	4
-73.172	-35.299	54	nan	13	4
-73.153	-35.304	55	nan	13	4
-73.132	-35.31	66	nan	13	4
-73.115	-35.316	84	nan	13	4
-73.095	-35.321	73	nan	13	4
-73.076	-35.326	83	nan	13	4
-73.673	-35.905	69	nan	13	4
-73.397	-35.904	69	nan	13	4
-71.35	-23.367	9.63	nan	14	1
-72.617	-31.417	31.4	nan	14	1
-66.923	-33.481	55.85	5.58	15	2
-61.957	-26.854	65.6	6.56	15	2
-66.775	-33.758	60.46	6.05	15	2
-66.795	-33.759	54.12	5.41	15	2
-68.194	-30.083	37.45	3.75	15	2
-62.105	-33.122	55.89	5.59	15	2
-62.772	-26.544	67.5	6.75	15	2
-61.775	-29.908	53.47	5.35	15	2
-61.832	-26.462	59.97	6	15	2
-66.615	-33.812	65.97	6.6	15	2
-62.395	-26.043	68.37	6.84	15	2
-64.783	-26.783	100.76	10.08	15	2
-66.68	-33.203	57.98	5.8	15	2
-61.549	-27.358	73.31	7.33	15	2
-63.97	-33.951	49.61	4.96	15	2
-68.596	-29.51	42.21	4.22	15	2
-67.585	-34.758	65.34	6.53	15	2
-61.996	-31.43	52.77	5.28	15	2
-61.128	-27.054	58.73	5.87	15	2
-61.26	-28.429	62.07	6.21	15	2
-68.46	-30.281	54.01	5.4	15	2
-67.15	-31.8	64.03	6.4	15	2
-64.024	-26.338	73.08	7.31	15	2
-64.136	-26.259	78.38	7.84	15	2
-62.652	-25.76	73.71	7.37	15	2
-67.116	-34.024	74.73	7.47	15	2
-67.16	-33.977	75.4	7.54	15	2
-63.149	-28.354	65.05	6.5	15	2
-68.593	-30.797	39.27	3.93	15	2
-68.584	-30.442	44.55	4.45	15	2
-63.752	-25.393	69.34	6.93	15	2
-62.827	-32.85	58.48	5.85	15	2
-60.072	-26.408	53.87	5.39	15	2
-68.367	-29.972	43.78	4.38	15	2
-69.347	-35.422	71.82	7.18	15	2
-66.96	-33.286	71.67	7.17	15	2
-62.863	-24.129	77.09	7.71	15	2
-62.069	-32.509	51.05	5.11	15	2
-66.978	-31.382	52.81	5.28	15	2
-68.856	-32.282	47.91	4.79	15	2
-62.956	-28.864	60.15	6.01	15	2
-66.68	-34.056	70.41	7.04	15	2
-69.894	-26.753	26.32	nan	16	2
-69.895	-26.754	28.56	nan	16	2
-69.895	-26.756	25.09	nan	16	2
-69.894	-26.756	29.78	nan	16	2
-70.617	-27.98	23.05	nan	16	2
-70.91	-28.666	13.46	nan	16	2